Question 1: 
const p = Promise.resolve('resolved')
//my code below to log the resolved value

const p = new Promise((resolve, reject) => {
  resolve("resolved");
});
p.then((value) => {
  console.log(value);
});


Question 2: // to come back, this ans is wrong
const p = Promise.reject(new Error('Oops!'));
//My code below to log the rejected reason 

const p = new Promise((resolve, reject) => {
  reject(new Error("oops!"));
});
p.then(value => {
  console.log("Resolved:", value);
}).catch(error => {
  console.error("errorrror:", error.message);
});


Question 3:
const p = Promise.resolve({ id: 1, name: 'Alice' });
// My code below to log the resolved value to the console:

const p = Promise.resolve({ id: 1, name: 'Alice' });
p.then(value => {
  console.log(value);
});

Question 4:
// Your code here
const p = Promise.resolve({ id: 1, name: 'Alice' });

p.then(({ name }) => {
  console.log(name);
});


Question 5:
// Your code here

Question 6:
// Your code here

Question 7:
// Your code here

Question 8:
// Your code here

Question 9:
// Your code here

Question 10:
// Your code here

Bonus Question:
// Your code here
